Traceback (most recent call last):
  File "/opt/hostedtoolcache/Python/3.8.12/x64/lib/python3.8/site-packages/jupyter_cache/executors/utils.py", line 51, in single_nb_execution
    executenb(
  File "/opt/hostedtoolcache/Python/3.8.12/x64/lib/python3.8/site-packages/nbclient/client.py", line 1204, in execute
    return NotebookClient(nb=nb, resources=resources, km=km, **kwargs).execute()
  File "/opt/hostedtoolcache/Python/3.8.12/x64/lib/python3.8/site-packages/nbclient/util.py", line 84, in wrapped
    return just_run(coro(*args, **kwargs))
  File "/opt/hostedtoolcache/Python/3.8.12/x64/lib/python3.8/site-packages/nbclient/util.py", line 62, in just_run
    return loop.run_until_complete(coro)
  File "/opt/hostedtoolcache/Python/3.8.12/x64/lib/python3.8/asyncio/base_events.py", line 616, in run_until_complete
    return future.result()
  File "/opt/hostedtoolcache/Python/3.8.12/x64/lib/python3.8/site-packages/nbclient/client.py", line 663, in async_execute
    await self.async_execute_cell(
  File "/opt/hostedtoolcache/Python/3.8.12/x64/lib/python3.8/site-packages/nbclient/client.py", line 965, in async_execute_cell
    await self._check_raise_for_error(cell, cell_index, exec_reply)
  File "/opt/hostedtoolcache/Python/3.8.12/x64/lib/python3.8/site-packages/nbclient/client.py", line 862, in _check_raise_for_error
    raise CellExecutionError.from_cell_and_msg(cell, exec_reply_content)
nbclient.exceptions.CellExecutionError: An error occurred while executing the following cell:
------------------
fig, ax = plt.subplots(1, 3, figsize=(10, 3), dpi=200)
ax[0].plot(me_history.history["loss"], label="MaxEnt")
ax[0].plot(hme_history.history["loss"], label="Hyper-MaxEnt")
ax[0].set_title(
    "loss (number of patches restrained: {})".format(len(restrained_patches))
)
ax[0].set_yscale("log")
ax[0].legend()

ax[1].plot(hme_history.history["weight-entropy"])
ax[1].set_title("weight entropy")

ax[2].plot(hme_history.history["prior-loss"])
ax[2].set_title("neg log-likelihood")
------------------

[0;31m---------------------------------------------------------------------------[0m
[0;31mNameError[0m                                 Traceback (most recent call last)
Input [0;32mIn [21][0m, in [0;36m<cell line: 2>[0;34m()[0m
[1;32m      1[0m fig, ax [38;5;241m=[39m plt[38;5;241m.[39msubplots([38;5;241m1[39m, [38;5;241m3[39m, figsize[38;5;241m=[39m([38;5;241m10[39m, [38;5;241m3[39m), dpi[38;5;241m=[39m[38;5;241m200[39m)
[0;32m----> 2[0m ax[[38;5;241m0[39m][38;5;241m.[39mplot([43mme_history[49m[38;5;241m.[39mhistory[[38;5;124m"[39m[38;5;124mloss[39m[38;5;124m"[39m], label[38;5;241m=[39m[38;5;124m"[39m[38;5;124mMaxEnt[39m[38;5;124m"[39m)
[1;32m      3[0m ax[[38;5;241m0[39m][38;5;241m.[39mplot(hme_history[38;5;241m.[39mhistory[[38;5;124m"[39m[38;5;124mloss[39m[38;5;124m"[39m], label[38;5;241m=[39m[38;5;124m"[39m[38;5;124mHyper-MaxEnt[39m[38;5;124m"[39m)
[1;32m      4[0m ax[[38;5;241m0[39m][38;5;241m.[39mset_title(
[1;32m      5[0m     [38;5;124m"[39m[38;5;124mloss (number of patches restrained: [39m[38;5;132;01m{}[39;00m[38;5;124m)[39m[38;5;124m"[39m[38;5;241m.[39mformat([38;5;28mlen[39m(restrained_patches))
[1;32m      6[0m )

[0;31mNameError[0m: name 'me_history' is not defined
NameError: name 'me_history' is not defined

